Workbook

Sheet CostosTodos
C2: LSOBB | D2: LVO | E2: ABB
A3: Total Altas exit. | C3: =LSO!E66 -> 17 | D3: =LVO!E66 -> 21 | E3: =ABB!E66 -> 21
A4: Max. Alta exit. | C4: =LSO!E67 -> 3 | D4: =LVO!E67 -> 1 | E4: =ABB!E67 -> 0.5
A5: Medio Alta exit. | C5: =LSO!E68 -> 0.941 | D5: =LVO!E68 -> 1 | E5: =ABB!E68 -> 0.5
A6: Total Bajas exit. | C6: =LSO!E69 -> 10 | D6: =LVO!E69 -> 14 | E6: =ABB!E69 -> 14
A7: Max. Baja exit. | C7: =LSO!E70 -> 6 | D7: =LVO!E70 -> 0.5 | E7: =ABB!E70 -> 1.5
A8: Medio Baja exit. | C8: =LSO!E71 -> 2.3 | D8: =LVO!E71 -> 0.5 | E8: =ABB!E71 -> 0.714
A9: Total evoc exit. | C9: =LSO!E72 -> 12 | D9: =LVO!E72 -> 14 | E9: =ABB!E72 -> 14
A10: Max. evoc exit. | C10: =LSO!E73 -> 4 | D10: =LVO!E73 -> 14 | E10: =ABB!E73 -> 5
A11: Medio evoc exit. | C11: =LSO!E74 -> 3.167 | D11: =LVO!E74 -> 5.357 | E11: =ABB!E74 -> 2.929
A12: Total evoc NO exit. | C12: =LSO!E75 -> 11 | D12: =LVO!E75 -> 8 | E12: =ABB!E75 -> 9
A13: Max. Evoc NO exit. | C13: =LSO!E76 -> 4 | D13: =LVO!E76 -> 8 | E13: =ABB!E76 -> 3
A14: Medio evoc NO exit. | C14: =LSO!E77 -> 2.182 | D14: =LVO!E77 -> 3.375 | E14: =ABB!E77 -> 2.111
C16: Recordar cambiar el tamaño del arreglo a 10

Sheet LSO
B1: operación | C1: dni | D1: Exito | E1: COSTO
A2: 1 | B2: Evoc | C2: 10000100 | D2: NO | E2: 0 | H2: ← puede no contarse
A3: =A2+1 -> 2 | B3: Alta | C3: 10000200 | D3: SI | E3: 0
A4: =A3+1 -> 3 | B4: Alta | C4: 10000150 | D4: SI | E4: 1
A5: =A4+1 -> 4 | B5: Alta | C5: 10000130 | D5: SI | E5: 2
A6: =A5+1 -> 5 | B6: Alta | C6: 10000110 | D6: SI | E6: 3
A7: =A6+1 -> 6 | B7: Alta | C7: 10000180 | D7: SI | E7: 1
A8: =A7+1 -> 7 | B8: Alta | C8: 10000160 | D8: SI | E8: 2
A9: =A8+1 -> 8 | B9: Alta | C9: 10000170 | D9: SI | E9: 2
A10: =A9+1 -> 9 | B10: Alta | C10: 10000200 | D10: NO | H10: ← repetido, dif may/min
A11: =A10+1 -> 10 | B11: Alta | C11: 10000110 | D11: NO | H11: ← repetido, dif may/min
A12: =A11+1 -> 11 | B12: Alta | C12: 10000150 | D12: NO | H12: ← repetido, dif may/min
A13: =A12+1 -> 12 | B13: Alta | C13: 10000210 | D13: SI | E13: 0
A14: =A13+1 -> 13 | B14: Alta | C14: 10000230 | D14: SI | E14: 0
A15: =A14+1 -> 14 | B15: Alta | C15: 10000220 | D15: SI | E15: 1
A16: =A15+1 -> 15 | B16: Alta | C16: 10000270 | D16: NO | H16: ← no ex en lista sec
A17: =A16+1 -> 16 | B17: Alta | C17: 10000290 | D17: NO | H17: ← no ex en lista sec
A18: =A17+1 -> 17 | B18: Alta | C18: 10000250 | D18: NO | H18: ← no ex en lista sec
A19: =A18+1 -> 18 | B19: Alta | C19: 10000260 | D19: NO | H19: ← no ex en lista sec
A20: =A19+1 -> 19 | B20: Evoc | C20: 10000230 | D20: SI | E20: 4
A21: =A20+1 -> 20 | B21: Evoc | C21: 10000200 | D21: SI | E21: 4
A22: =A21+1 -> 21 | B22: Evoc | C22: 10000110 | D22: SI | E22: 4
A23: =A22+1 -> 22 | B23: Evoc | C23: 10000170 | D23: SI | E23: 3
A24: =A23+1 -> 23 | B24: Evoc | C24: 10000160 | D24: SI | E24: 3
A25: =A24+1 -> 24 | B25: Evoc | C25: 10000290 | D25: NO | E25: 4 | H25: ← no ex en lista sec
A26: =A25+1 -> 25 | B26: Baja | C26: 10000200 | D26: SI | E26: 3
A27: =A26+1 -> 26 | B27: Evoc | C27: 10000200 | D27: NO | E27: 3
A28: =A27+1 -> 27 | B28: Evoc | C28: 10000220 | D28: SI | E28: 3
A29: =A28+1 -> 28 | B29: Evoc | C29: 10000180 | D29: SI | E29: 3
A30: =A29+1 -> 29 | B30: Baja | C30: 10000230 | D30: SI | E30: 0
A31: =A30+1 -> 30 | B31: Baja | C31: 10000130 | D31: SI | E31: 6
A32: =A31+1 -> 31 | B32: Baja | C32: 10000180 | D32: SI | E32: 2
A33: =A32+1 -> 32 | B33: Evoc | C33: 10000110 | D33: SI | E33: 3
A34: =A33+1 -> 33 | B34: Baja | C34: 10000110 | D34: SI | E34: 5
A35: =A34+1 -> 34 | B35: Evoc | C35: 10000110 | D35: NO | E35: 3
A36: =A35+1 -> 35 | B36: Baja | C36: 10000160 | D36: SI | E36: 3
A37: =A36+1 -> 36 | B37: Baja | C37: 10000210 | D37: SI | E37: 1
... A42: =A41+1 -> 41 | B42: Baja | C42: 10000220 | D42: SI | E42: 0
A43: =A42+1 -> 42 | B43: Evoc | C43: 10000290 | D43: NO | E43: 0 | G43: vacía | H43: ← puede no contarse
A44: =A43+1 -> 43 | B44: Baja | C44: 10000290 | D44: NO | G44: vacía | H44: ← no ex en lista sec
...

Sheet LVO
B1: operación | C1: dni | D1: Exito | E1: COSTO
A2: 1 | B2: Evoc | C2: 10000100 | D2: NO | E2: 1 | H2: ← puede no contarse o ser 0
A3: =A2+1 -> 2 | B3: Alta | C3: 10000200 | D3: SI | E3: 1
A4: =A3+1 -> 3 | B4: Alta | C4: 10000150 | D4: SI | E4: 1
A5: =A4+1 -> 4 | B5: Alta | C5: 10000130 | D5: SI | E5: 1
A6: =A5+1 -> 5 | B6: Alta | C6: 10000110 | D6: SI | E6: 1
A7: =A6+1 -> 6 | B7: Alta | C7: 10000180 | D7: SI | E7: 1
A8: =A7+1 -> 7 | B8: Alta | C8: 10000160 | D8: SI | E8: 1
A9: =A8+1 -> 8 | B9: Alta | C9: 10000170 | D9: SI | E9: 1
A10: =A9+1 -> 9 | B10: Alta | C10: 10000200 | D10: NO | H10: ← repetido, dif may/min
A11: =A10+1 -> 10 | B11: Alta | C11: 10000110 | D11: NO | H11: ← repetido, dif may/min
A12: =A11+1 -> 11 | B12: Alta | C12: 10000150 | D12: NO | H12: ← repetido, dif may/min
A13: =A12+1 -> 12 | B13: Alta | C13: 10000210 | D13: SI | E13: 1
A14: =A13+1 -> 13 | B14: Alta | C14: 10000230 | D14: SI | E14: 1
A15: =A14+1 -> 14 | B15: Alta | C15: 10000220 | D15: SI | E15: 1
A16: =A15+1 -> 15 | B16: Alta | C16: 10000270 | D16: SI | E16: 1 | H16: ← no ex en lista sec
A17: =A16+1 -> 16 | B17: Alta | C17: 10000290 | D17: SI | E17: 1 | H17: ← no ex en lista sec
A18: =A17+1 -> 17 | B18: Alta | C18: 10000250 | D18: SI | E18: 1 | H18: ← no ex en lista sec
A19: =A18+1 -> 18 | B19: Alta | C19: 10000260 | D19: SI | E19: 1 | H19: ← no ex en lista sec
A20: =A19+1 -> 19 | B20: Evoc | C20: 10000230 | D20: SI | E20: 10
A21: =A20+1 -> 20 | B21: Evoc | C21: 10000200 | D21: SI | E21: 7
A22: =A21+1 -> 21 | B22: Evoc | C22: 10000110 | D22: SI | E22: 1
A23: =A22+1 -> 22 | B23: Evoc | C23: 10000170 | D23: SI | E23: 5
A24: =A23+1 -> 23 | B24: Evoc | C24: 10000160 | D24: SI | E24: 4
A25: =A24+1 -> 24 | B25: Evoc | C25: 10000290 | D25: SI | E25: 14 | H25: ← no ex en lista sec
A26: =A25+1 -> 25 | B26: Baja | C26: 10000200 | D26: SI | E26: 0.5
A27: =A26+1 -> 26 | B27: Evoc | C27: 10000200 | D27: NO | E27: 7
A28: =A27+1 -> 27 | B28: Evoc | C28: 10000220 | D28: SI | E28: 8
A29: =A28+1 -> 28 | B29: Evoc | C29: 10000180 | D29: SI | E29: 6
A30: =A29+1 -> 29 | B30: Baja | C30: 10000230 | D30: SI | E30: 0.5
A31: =A30+1 -> 30 | B31: Baja | C31: 10000130 | D31: SI | E31: 0.5
A32: =A31+1 -> 31 | B32: Baja | C32: 10000180 | D32: SI | E32: 0.5
A33: =A32+1 -> 32 | B33: Evoc | C33: 10000110 | D33: SI | E33: 1
A34: =A33+1 -> 33 | B34: Baja | C34: 10000110 | D34: SI | E34: 0.5
A35: =A34+1 -> 34 | B35: Evoc | C35: 10000110 | D35: NO | E35: 1
A36: =A35+1 -> 35 | B36: Baja | C36: 10000160 | D36: SI | E36: 0.5
A37: =A36+1 -> 36 | B37: Baja | C37: 10000210 | D37: SI | E37: 0.5
... A42: =A41+1 -> 41 | B42: Baja | C42: 10000220 | D42: SI | E42: 0.5
A43: =A42+1 -> 42 | B43: Evoc | C43: 10000290 | D43: SI | E43: 4 | H43: ← no ex en lista sec
A44: =A43+1 -> 43 | B44: Baja | C44: 10000290 | D44: SI | E44: 0.5 | H44: ← no ex en lista sec
...

Sheet ABB
B1: operación | C1: dni | D1: Exito | E1: COSTO
A2: 1 | B2: Evoc | C2: 10000100 | D2: NO | E2: 0 | H2: ← puede no contarse
A3: =A2+1 -> 2 | B3: Alta | C3: 10000200 | D3: SI | E3: 0.5
A4: =A3+1 -> 3 | B4: Alta | C4: 10000150 | D4: SI | E4: 0.5
A5: =A4+1 -> 4 | B5: Alta | C5: 10000130 | D5: SI | E5: 0.5
A6: =A5+1 -> 5 | B6: Alta | C6: 10000110 | D6: SI | E6: 0.5
A7: =A6+1 -> 6 | B7: Alta | C7: 10000180 | D7: SI | E7: 0.5
A8: =A7+1 -> 7 | B8: Alta | C8: 10000160 | D8: SI | E8: 0.5
A9: =A8+1 -> 8 | B9: Alta | C9: 10000170 | D9: SI | E9: 0.5
A10: =A9+1 -> 9 | B10: Alta | C10: 10000200 | D10: NO | H10: ← repetido, dif may/min
A11: =A10+1 -> 10 | B11: Alta | C11: 10000110 | D11: NO | H11: ← repetido, dif may/min
A12: =A11+1 -> 11 | B12: Alta | C12: 10000150 | D12: NO | H12: ← repetido, dif may/min
A13: =A12+1 -> 12 | B13: Alta | C13: 10000210 | D13: SI | E13: 0.5
A14: =A13+1 -> 13 | B14: Alta | C14: 10000230 | D14: SI | E14: 0.5
A15: =A14+1 -> 14 | B15: Alta | C15: 10000220 | D15: SI | E15: 0.5
A16: =A15+1 -> 15 | B16: Alta | C16: 10000270 | D16: SI | E16: 0.5 | H16: ← no ex en lista sec
A17: =A16+1 -> 16 | B17: Alta | C17: 10000290 | D17: SI | E17: 0.5 | H17: ← no ex en lista sec
A18: =A17+1 -> 17 | B18: Alta | C18: 10000250 | D18: SI | E18: 0.5 | H18: ← no ex en lista sec
A19: =A18+1 -> 18 | B19: Alta | C19: 10000260 | D19: SI | E19: 0.5 | H19: ← no ex en lista sec
A20: =A19+1 -> 19 | B20: Evoc | C20: 10000230 | D20: SI | E20: 3
A21: =A20+1 -> 20 | B21: Evoc | C21: 10000200 | D21: SI | E21: 1
A22: =A21+1 -> 21 | B22: Evoc | C22: 10000110 | D22: SI | E22: 4
A23: =A22+1 -> 22 | B23: Evoc | C23: 10000170 | D23: SI | E23: 5
A24: =A23+1 -> 23 | B24: Evoc | C24: 10000160 | D24: SI | E24: 4
A25: =A24+1 -> 24 | B25: Evoc | C25: 10000290 | D25: SI | E25: 5 | H25: ← no ex en lista sec
A26: =A25+1 -> 25 | B26: Baja | C26: 10000200 | D26: SI | E26: 1.5
A27: =A26+1 -> 26 | B27: Evoc | C27: 10000200 | D27: NO | E27: 3
A28: =A27+1 -> 27 | B28: Evoc | C28: 10000220 | D28: SI | E28: 3
A29: =A28+1 -> 28 | B29: Evoc | C29: 10000180 | D29: SI | E29: 3
A30: =A29+1 -> 29 | B30: Baja | C30: 10000230 | D30: SI | E30: 1.5
A31: =A30+1 -> 30 | B31: Baja | C31: 10000130 | D31: SI | E31: 0.5
A32: =A31+1 -> 31 | B32: Baja | C32: 10000180 | D32: SI | E32: 0.5
A33: =A32+1 -> 32 | B33: Evoc | C33: 10000110 | D33: SI | E33: 3
A34: =A33+1 -> 33 | B34: Baja | C34: 10000110 | D34: SI | E34: 0.5
A35: =A34+1 -> 34 | B35: Evoc | C35: 10000110 | D35: NO | E35: 2
A36: =A35+1 -> 35 | B36: Baja | C36: 10000160 | D36: SI | E36: 0.5
A37: =A36+1 -> 36 | B37: Baja | C37: 10000210 | D37: SI | E37: 1.5
... A42: =A41+1 -> 41 | B42: Baja | C42: 10000220 | D42: SI | E42: 0.5
A43: =A42+1 -> 42 | B43: Evoc | C43: 10000290 | D43: SI | E43: 3 | H43: ← no ex en lista sec
A44: =A43+1 -> 43 | B44: Baja | C44: 10000290 | D44: SI | E44: 0.5 | H44: ← no ex en lista sec
...
